Workbook

Sheet 包边
D1: 安徽江福科技有限公司 | E1: 编号： | L1: 日期
E2: 设计人员： | G2: =[40]目录!H10 | L2: =[40]目录!J10
D3: 模具自检表 | E3: 校对人员: | G3: =[40]目录!H11 | L3: =[40]目录!J11
A4: 产品名: | B4: =[40]目录!H5 | C4: 工序内容： | D4: =[40]目录!H7 | E4: 审核人员： | G4: =[40]目录!H12 | L4: =[40]目录!J12
A5: 模具图号: | B5: =[40]目录!H8 | C5: 使用设备： | D5: =[40]目录!H9
A6: NO. | E6: 设计填写栏 | H6: 校审填写栏 | K6: 备注
E7: 阶段 | H7: 阶段
B8: 一.共性内容检查 | E8: 内审 | F8: FMC | G8: 正式图 | H8: 内审 | I8: FMC | J8: 正式图 | M8: 统计 | R8: 链接到目录
A9: 1 | N9: 结果 | O9: 项数 | P9: 比例
A10: 2 | B10: 模具中心是否与绝对坐标中心一致 | M10: 内审 | N10: √ | O10: =COUNTIF(H9:H99,"√") | P10: =O10/Q12
A11: 3 | B11: CH孔位置尺寸是否与工艺数模一致（特别注意CH孔的工法方向），CH凸模吃入量超出料厚2-3mm；（2017-07-25） | N11: × | O11: =COUNTIF(H9:H99,"×") | P11: =O11/Q12 | Q11: 总计
A12: 4 | B12: 模具筋条尽量不要与机床T槽重合;模具筋条边缘与机床T槽边缘距离最少5mm，如重合筋条底面补肉大于T槽边缘单边10mm（2023-8-7） | N12: 无 | O12: =COUNTIF(H9:H99,"无") | P12: =O12/Q12 | Q12: =SUM(O10:O12)
A13: 5 | E13: √ | M13: FMC | N13: √ | O13: =COUNTIF(I9:I99,"√") | P13: =O13/Q15
A14: 6 | N14: × | O14: =COUNTIF(I9:I99,"×") | P14: =O14/Q15 | Q14: 总计
A15: 7 | N15: 无 | O15: =COUNTIF(I9:I99,"无") | P15: =O15/Q15 | Q15: =SUM(O13:O15)
A16: 8
A17: 9 | B17: 是否有说明层：包括模具行程图、顶杆布置图（拉延）、斜楔行程图以及相关冲裁力压料力的计算；
A18: 10 | B18: 模具运输连接板、漏水孔、导板窥视孔（导腿处、压芯托芯导滑处、DR凸模处）、墩死块窥视孔、过线孔、快速定位窥视孔是否设计；
A19: 11 | B19: 电路盒、气路接头放置位置符合客户要求？检查电、气路过线是否畅通，感应器过线孔通常要开在感应器正下方，方便安装；（2023-8-7）
A20: 12 | B20: 压力源（顶杆）行程是否与压芯、托芯、小凸芯、压边圈行程一致；安全行程为ST+15mm（DR为ST+20mm）；工作侧销能否用双槽（有CAM、氮气弹簧时不能用）；
A21: 13 | B21: 压料芯行程（工作限位间距）为整0或整5，氮气缸行程比侧销限位行程少2mm， 使用行程最大为氮气缸行程的90%；氮气弹簧余量最少5mm（2023-8-7）
A22: 14 | B22: 检查氮气弹簧与对顶块接触情况（接触面＞90%），不要顶在螺钉孔上（2023-8-7）
A23: 15 | B23: 压芯走框架结构处刀块是否按最小高度设计（锻件min35mm，铸件min50mm），刀块螺孔销孔是否悬空，螺孔销孔距离铸件边界最少10mm；
A24: 16 | B24: 修边模和冲孔模等，即使是压芯没有墩死块的模具，也必须在压芯上设置基准面（4个即可）；
A25: 17 | B25: 工作、安全螺栓的长度要求全部相同；
A26: 18
A27: 19 | B27: 安全平台、传力部位及工作部位下要有加强或有筋支撑？限位块、墩死块支撑面积≥限位块面积的一半 （2023-8-7）
A28: 20 | B28: 原则上压芯、凸模、大型斜楔设计起吊翻转，位置合理，17kg以上的镶块需设置起吊孔，规格为M16，所有镶块禁止用M6及M6以下螺钉锁符，但同时所有镶块都要考虑拆装方便性，适当增加起吊孔；（2017-07-25）
A29: 21 | B29: 定位键安装槽直边长度要比定位键单边长1mm，刀块上定位键卡槽要比安装槽单边长5mm；
A30: 22 | B30: 运输连接板安装孔采用CSN16铸入式螺栓，有客户特殊要求的按客户要求；
A31: 23 | B31: 模具取件装置：A 空手槽；B 气缸；C 机械手（吸盘）；D 其它；
A32: 24 | B32: 上、下模镶块的拼接缝最小错开5毫米；（2023-8-7）
A33: 25 | B33: 标准件安装面比标准件大5mm，若无法满足，则需要贴量加工保证；
A34: 26 | B34: 铸造孔是否满足要求（1.盲孔：直径≥50，高度与直径比≤1.5；2.通孔：直径≥40，高度与直径比≤2.5；3.筋板上的穿线孔、漏水孔≥40）；若不能满足，需贴量加工；
A35: 27 | B35: 检查导板与导滑面是否错位，压料芯氮气弹簧与氮气弹簧安装面、氮气弹簧过渡垫块及过渡垫块安装面之间是否存在错位现象；
A36: 28 | B36: 整体热处理镶块孔边缘距离镶块边缘（壁厚）≥8mm；
A37: 29 | B37: 检查铸件X、Y、Z方向的断面，是否存在过厚过薄处；
A38: 30 | B38: 确认氮气弹簧是否需要串联；串联实体表示出来 | K38: 新增
A39: 31 | B39: 拆卸压料芯前需要拆除的刀块都要标识“X”； | K39: 新增
A40: 32 | B40: 模具的各部件的行程关系都已经分析，且有行程关系图，压料板行程及压力工艺特别指示需与工艺模拟完全一致 | K40: 新增
...
