Workbook

Sheet 机床参数检查表
C1: 安徽江福科技有限公司 | H1: 编号： | L1: 日期
H2: 设计人员： | J2: =[40]目录!H10 | L2: =[40]目录!J10 | M2: 结论 | N2: =IF(O14+O18+O21=0,"OK","NG")
C3: 模具自检表 | H3: 校对人员: | J3: =[40]目录!H11 | L3: =[40]目录!J11
A4: 产品名: | C4: =[40]目录!H5 | H4: 审核人员： | J4: =[40]目录!H12 | L4: =[40]目录!J12
A5: 模具图号: | C5: =[40]目录!H8 | E5: OK：√ NG：× 无检查项：无
A6: NO. | B6: 检 查 点 | H6: 自检 | I6: 审核 | J6: 备注 | Q6: S
A8: 1 | B8: 生产方式是否正确；（手动生产/自动线生产） | H8: OK | M8: 统计
A9: 2 | B9: 送料方式的正确性；（平动送料/旋转180°送料） | H9: OK | N9: 结果 | O9: 项数 | P9: 比例
A10: 3 | C10: 3.1 机床使用 | H10: OK | M10: 自检 | N10: √ | O10: =COUNTIF(H8:H26,"√") | P10: =O10/Q12 | R10: 链接到目录
C11: 3.2 压板槽 | D11: 与机床库实体的一致性检查，含位置、尺寸、快夹行程、装夹空间等 | H11: OK | N11: × | O11: =COUNTIF(H8:H26,"×") | P11: =O11/Q12 | Q11: 总计
C12: 3.3 键槽/通槽 | H12: OK | N12: 无 | O12: =COUNTIF(H8:H26,"无") | P12: =O12/Q12 | Q12: =SUM(O10:O12)
C13: 3.4 快速定位 | H13: OK | M13: 审核 | N13: √ | O13: =COUNTIF(I8:I26,"√") | P13: =O13/Q15
C14: 3.5 顶杆 | H14: OK | N14: × | O14: =COUNTIF(I8:I26,"×") | P14: =O14/Q15 | Q14: 总计
A15: 4 | C15: 4.1 闭模高度 | H15: OK | N15: 无 | O15: =COUNTIF(I8:I26,"无") | P15: =O15/Q15 | Q15: =SUM(O13:O15)
C16: 4.2 存放高度 | H16: OK | M16: 审核
C17: 4.3 通过性 | D17: 模具工作、存放状态下是否满足设备侧移门高度要求: | H17: OK | M17: 主 | N17: OK | O17: =COUNTIFS(J33:J56,"ok")
A18: 5 | C18: 自动线前后序送料高度落差是否符合要求,前后序送料高尺寸偏差数值(100MM )；(一个件统一排查，每个项目都需要单独确认）。 | H18: OK | N18: NG | O18: =COUNTIFS(J33:J56,"NG")
A19: 6 | C19: 6.1 横杆位置 | D19: 是否有自动化干涉曲线? 若有，横杆位置和高度是否正确？ | H19: OK | N19: 无 | O19: =COUNTIFS(J33:J56,"无")
C20: 6.2 干涉空间 | H20: OK | M20: 副 | N20: OK | O20: =COUNTIFS(J63:J84,"ok")
A21: 7 | B21: 设备负荷 | H21: OK | N21: NG | O21: =COUNTIFS(J63:J84,"NG")
A22: 8 | H22: OK | N22: 无 | O22: =COUNTIFS(J63:J84,"无")
A23: 9 | B23: 是否成线生产； | H23: OK
A24: 10 | H24: OK
A25: 11 | H25: OK
A26: 12 | H26: OK | J26: 乘用车二厂：行车：大钩40，小钩16.宋方金2017.10
A27: 主线机床检查
A31: 截图核查项
A32: 主项次 | B32: 分项次 | C32: 内容 | D32: 设计自检贴图栏 | F32: 审核贴图栏 | J32: 结论 | K32: 备注
A33: 3.机床通用参数的正确性 | B33: 3.1
B35: 3.2
B39: 3.3
B41: 3.4
B43: 3.5
A45: 4.模具闭合高度 | B45: 4.1
A47: 5.自动线送料高 | B47: 5.1
A49: 6.自动线取料 | B49: 6.1
B51: 6.2
A53: 8.偏心检查 | B53: 8.1
A55: 9.排料检查 | B55: 9.1
A57: 副线机床检查
...
